<?xml version="1.0" ?>
<!-- =================================================================================== -->
<!-- |    This document was autogenerated by xacro from /home/kimsooyoung/ros2_ws/src/SRC-ROS-2/src_description/urdf/racecar.urdf.xacro | -->
<!-- |    EDITING THIS FILE BY HAND IS NOT RECOMMENDED                                 | -->
<!-- =================================================================================== -->
<robot name="racecar">
  <!-- inertial parameter macros -->
  <!-- geometry macros -->
  <material name="black">
    <color rgba="0.0 0.0 0.0 1.0"/>
  </material>
  <material name="blue">
    <color rgba="0.0 0.0 0.8 1.0"/>
  </material>
  <material name="green">
    <color rgba="0.0 0.8 0.0 1.0"/>
  </material>
  <material name="grey">
    <color rgba="0.2 0.2 0.2 1.0"/>
  </material>
  <material name="orange">
    <color rgba="1.0 0.4235294117647059 0.0392156862745098 1.0"/>
  </material>
  <material name="brown">
    <color rgba="0.8705882352941177 0.8117647058823529 0.7647058823529411 1.0"/>
  </material>
  <material name="red">
    <color rgba="0.8 0.0 0.0 1.0"/>
  </material>
  <material name="white">
    <color rgba="1.0 1.0 1.0 1.0"/>
  </material>
  <!-- we don't need gazebo file now -->
  <!-- <xacro:include filename="$(find src_description)/urdf/racecar.gazebo" /> -->
  <link name="base_link"/>
  <link name="chassis">
    <visual>
      <origin rpy="0 0 0" xyz="0 0 0"/>
      <geometry>
        <mesh filename="model://src_ackermann/meshes/chassis.STL"/>
      </geometry>
      <material name="blue"/>
    </visual>
  </link>
  <joint name="base_link_joint" type="fixed">
    <origin rpy="0 0 0" xyz="0 0 0.05"/>
    <parent link="base_link"/>
    <child link="chassis"/>
  </joint>
  <link name="chassis_inertia">
    <inertial>
      <origin rpy="0 0 0" xyz="0.1477 0 0"/>
      <mass value="4.0"/>
      <inertia ixx="0.010609" ixy="0" ixz="0" iyy="0.050409" iyz="0" izz="0.05865"/>
    </inertial>
  </link>
  <joint name="chassis_inertia_joint" type="fixed">
    <origin rpy="0 0 0" xyz="0 0 0"/>
    <parent link="chassis"/>
    <child link="chassis_inertia"/>
  </joint>
  <link name="left_rear_wheel">
    <inertial>
      <origin rpy="0 0 0" xyz="0 0 -0.0225"/>
      <mass value="0.34055"/>
      <inertia ixx="0.00026046" ixy="0" ixz="0" iyy="0.00026046" iyz="0" izz="0.00041226"/>
    </inertial>
    <visual>
      <origin rpy="0 0 0" xyz="0 0 0"/>
      <geometry>
        <mesh filename="model://src_ackermann/meshes/left_rear_wheel.STL"/>
      </geometry>
      <material name="black"/>
    </visual>
    <collision>
      <origin rpy="0 0 0" xyz="0 0 -0.0225"/>
      <geometry>
        <cylinder length="0.045" radius="0.05"/>
      </geometry>
    </collision>
  </link>
  <joint name="left_rear_wheel_joint" type="continuous">
    <origin rpy="1.5708 0 0" xyz="0 0.1 0"/>
    <parent link="chassis"/>
    <child link="left_rear_wheel"/>
    <axis xyz="0 0 -1"/>
    <limit effort="10" velocity="100"/>
  </joint>
  <link name="right_rear_wheel">
    <inertial>
      <origin rpy="0 0 0" xyz="0 0 0.0225"/>
      <mass value="0.34055"/>
      <inertia ixx="0.00026046" ixy="0" ixz="0" iyy="0.00026046" iyz="0" izz="0.00041226"/>
    </inertial>
    <visual>
      <origin rpy="0 0 0" xyz="0 0 0"/>
      <geometry>
        <mesh filename="model://src_ackermann/meshes/right_rear_wheel.STL"/>
      </geometry>
      <material name="black"/>
    </visual>
    <collision>
      <origin rpy="0 0 0" xyz="0 0 0.0225"/>
      <geometry>
        <cylinder length="0.045" radius="0.05"/>
      </geometry>
    </collision>
  </link>
  <joint name="right_rear_wheel_joint" type="continuous">
    <origin rpy="1.5708 0 0" xyz="0 -0.1 0"/>
    <parent link="chassis"/>
    <child link="right_rear_wheel"/>
    <axis xyz="0 0 -1"/>
    <limit effort="10" velocity="100"/>
  </joint>
  <link name="left_steering_hinge">
    <inertial>
      <origin rpy="0 0 0" xyz="0 0 0"/>
      <mass value="0.100"/>
      <inertia ixx="4E-06" ixy="0" ixz="0" iyy="4E-06" iyz="0" izz="4E-06"/>
    </inertial>
    <visual>
      <origin rpy="0 0 0" xyz="0 0 0"/>
      <geometry>
        <mesh filename="model://src_ackermann/meshes/left_steering_hinge.STL"/>
      </geometry>
      <material name="grey"/>
    </visual>
  </link>
  <joint name="left_steering_hinge_joint" type="revolute">
    <origin rpy="0 1.5708 0" xyz="0.325 0.1 0"/>
    <parent link="chassis"/>
    <child link="left_steering_hinge"/>
    <axis xyz="-1 0 0"/>
    <limit effort="10" lower="-0.7853" upper="0.7853" velocity="100"/>
  </joint>
  <link name="right_steering_hinge">
    <inertial>
      <origin rpy="0 0 0" xyz="0 0 0"/>
      <mass value="0.100"/>
      <inertia ixx="4E-06" ixy="0" ixz="0" iyy="4E-06" iyz="0" izz="4E-06"/>
    </inertial>
    <visual>
      <origin rpy="0 0 0" xyz="0 0 0"/>
      <geometry>
        <mesh filename="model://src_ackermann/meshes/right_steering_hinge.STL"/>
      </geometry>
      <material name="grey"/>
    </visual>
  </link>
  <joint name="right_steering_hinge_joint" type="continuous">
    <origin rpy="0 1.5708 0" xyz="0.325 -0.1 0"/>
    <parent link="chassis"/>
    <child link="right_steering_hinge"/>
    <axis xyz="-1 0 0"/>
    <limit effort="10" lower="-0.7853" upper="0.7853" velocity="100"/>
  </joint>
  <link name="left_front_wheel">
    <inertial>
      <origin rpy="0 0 0" xyz="0 0 -0.0225"/>
      <mass value="0.34055"/>
      <inertia ixx="0.00026046" ixy="0" ixz="0" iyy="0.00026046" iyz="0" izz="0.00041226"/>
    </inertial>
    <visual>
      <origin rpy="0 0 0" xyz="0 0 0"/>
      <geometry>
        <mesh filename="model://src_ackermann/meshes/left_front_wheel.STL"/>
      </geometry>
      <material name="black"/>
    </visual>
    <collision>
      <origin rpy="0 0 0" xyz="0 0 -0.0225"/>
      <geometry>
        <cylinder length="0.045" radius="0.05"/>
      </geometry>
    </collision>
  </link>
  <joint name="left_front_wheel_joint" type="continuous">
    <origin rpy="1.5708 0 0" xyz="0 0 0"/>
    <parent link="left_steering_hinge"/>
    <child link="left_front_wheel"/>
    <axis xyz="0 0 -1"/>
    <limit effort="10" velocity="100"/>
  </joint>
  <link name="right_front_wheel">
    <inertial>
      <origin rpy="0 0 0" xyz="0 0 0.0225"/>
      <mass value="0.34055"/>
      <inertia ixx="0.00026046" ixy="0" ixz="0" iyy="0.00026046" iyz="0" izz="0.00041226"/>
    </inertial>
    <visual>
      <origin rpy="0 0 0" xyz="0 0 0"/>
      <geometry>
        <mesh filename="model://src_ackermann/meshes/right_front_wheel.STL"/>
      </geometry>
      <material name="black"/>
    </visual>
    <collision>
      <origin rpy="0 0 0" xyz="0 0 0.0225"/>
      <geometry>
        <cylinder length="0.045" radius="0.05"/>
      </geometry>
    </collision>
  </link>
  <joint name="right_front_wheel_joint" type="continuous">
    <origin rpy="1.5708 0 0" xyz="0 0 0"/>
    <parent link="right_steering_hinge"/>
    <child link="right_front_wheel"/>
    <axis xyz="0 0 -1"/>
    <limit effort="10" velocity="100"/>
  </joint>
  <link name="laser">
    <inertial>
      <origin rpy="0 0 0" xyz="0 0 0"/>
      <mass value="0.130"/>
      <inertia ixx="4E-06" ixy="0" ixz="0" iyy="4E-06" iyz="0" izz="4E-06"/>
    </inertial>
    <collision>
      <origin rpy="0 0 0" xyz="0 0 0"/>
      <geometry>
        <box size="0.1 0.1 0.1"/>
      </geometry>
    </collision>
    <visual>
      <origin rpy="0 0 0" xyz="0 0 0"/>
      <geometry>
        <mesh filename="model://src_ackermann/meshes/hokuyo.dae"/>
        <material name="grey"/>
      </geometry>
    </visual>
  </link>
  <joint name="hokuyo_joint" type="fixed">
    <origin rpy="0 0 0" xyz="0.265 0.0 0.075"/>
    <parent link="chassis"/>
    <child link="laser"/>
    <axis xyz="0 0 1"/>
  </joint>
  <link name="zed_camera_link">
    <inertial>
      <mass value="1e-5"/>
      <origin rpy="0 0 0" xyz="0 0 0"/>
      <inertia ixx="1e-6" ixy="0" ixz="0" iyy="1e-6" iyz="0" izz="1e-6"/>
    </inertial>
    <collision>
      <origin rpy="0 0 0" xyz="0 0 0"/>
      <geometry>
        <box size="0.033 0.175 0.030"/>
      </geometry>
    </collision>
    <visual>
      <origin rpy="0 0 0" xyz="0 0 0"/>
      <geometry>
        <box size="0.033 0.175 0.030"/>
      </geometry>
      <material name="red"/>
    </visual>
  </link>
  <joint name="zed_camera_joint" type="fixed">
    <origin rpy="0 0 0" xyz="0.390 0 0.04"/>
    <parent link="chassis"/>
    <child link="zed_camera_link"/>
    <axis xyz="0 0 1"/>
    <!-- <limit lower="0.0" upper="0.0" effort="0.0" velocity="0.0" /> -->
  </joint>
  <!-- zed camera lenses -->
  <!-- It seems these have to have a non-zero mass to have a camera attached? -->
  <!-- this needs to match the name in zed_wrapper/zed_tf.launch -->
  <link name="camera_link">
    <inertial>
      <mass value="1e-5"/>
      <origin rpy="0 0 0" xyz="0 0 0"/>
      <inertia ixx="1e-6" ixy="0" ixz="0" iyy="1e-6" iyz="0" izz="1e-6"/>
    </inertial>
  </link>
  <link name="zed_camera_right_link">
    <inertial>
      <mass value="1e-5"/>
      <origin rpy="0 0 0" xyz="0 0 0"/>
      <inertia ixx="1e-6" ixy="0" ixz="0" iyy="1e-6" iyz="0" izz="1e-6"/>
    </inertial>
  </link>
  <joint name="zed_camera_left_joint" type="fixed">
    <origin rpy="0 0 0" xyz="0 0.06 0"/>
    <parent link="zed_camera_link"/>
    <child link="camera_link"/>
    <axis xyz="0 0 1"/>
  </joint>
  <joint name="zed_camera_right_joint" type="fixed">
    <origin rpy="0 0 0" xyz="0 -0.06 0"/>
    <parent link="zed_camera_link"/>
    <child link="zed_camera_right_link"/>
    <axis xyz="0 0 1"/>
  </joint>
  <link name="imu_link">
    <inertial>
      <mass value="0.01"/>
      <inertia ixx="1.0" ixy="0" ixz="0" iyy="1.0" iyz="0" izz="1.0"/>
    </inertial>
  </link>
  <joint name="imu_joint" type="fixed">
    <origin rpy="0 0 0" xyz="0.01 0 0"/>
    <parent link="zed_camera_link"/>
    <child link="imu_link"/>
    <!-- <axis xyz="0 0 1" /> -->
  </joint>
</robot>
